<mujoco model="am_scene">

    <compiler angle="radian" coordinate="local"/>
    <option gravity="0 0 -9.81" timestep="0.002"/>

    <visual>
        <headlight ambient="0.2 0.2 0.2" diffuse="0.4 0.4 0.4" specular="0.0 0.0 0.0"/>
        <quality shadowsize="8192"/>
        <map znear="0.005" zfar="100"/>
        <rgba haze="0.15 0.25 0.35 1"/>
    </visual>

    <asset>
        <!-- Fine grid floor — tight spacing helps perceive height and lateral speed -->
        <texture name="grid" type="2d" builtin="checker" width="1024" height="1024"
                 rgb1="0.45 0.45 0.45" rgb2="0.65 0.65 0.65"/>
        <material name="grid_mat" texture="grid" texrepeat="5 5" texuniform="true"
                  reflectance="0.05"/>
        <!-- Sky gradient: bright horizon → deep blue zenith -->
        <texture name="sky" type="skybox" builtin="gradient"
                 rgb1="0.75 0.88 1.0" rgb2="0.08 0.18 0.45" width="512" height="512"/>
    </asset>

    <default>
        <joint damping="0.02"/>
        <geom contype="1" conaffinity="1"/>
        <default class="visual">
            <geom contype="0" conaffinity="0" mass="0"/>
        </default>
    </default>

    <worldbody>

        <!-- Ground: fine grid gives strong height/speed perception cues -->
        <geom name="ground" type="plane" size="30 30 0.1" material="grid_mat"/>

        <!-- Height reference poles at 1 m intervals -->
        <!-- <geom type="cylinder" pos="3 0 1"   size="0.02 1"   rgba="1 0.3 0.3 0.6"/>
        <geom type="cylinder" pos="3 0 3"   size="0.02 1"   rgba="1 0.6 0.0 0.6"/>
        <geom type="cylinder" pos="3 0 5"   size="0.02 1"   rgba="0.3 1 0.3 0.6"/> -->
        <!-- 1m / 3m / 5m band labels baked into colours (red/orange/green) -->

        <!-- Cameras -->
        <camera name="track" mode="trackcom" pos="3 -3 2" xyaxes="1 1 0 -0.4 0.4 1"/>
        <camera name="side"  mode="trackcom" pos="0 -5 1.5" xyaxes="1 0 0 0 0.3 1"/>
        <camera name="fixed" pos="4 4 3" xyaxes="-1 1 0 -0.5 -0.5 1"/>

        <!-- Sun-like directional light with shadows -->
        <light name="main_light"
           pos="0 0 5"
           dir="0 0 -1"
           diffuse="0.8 0.8 0.8"
           specular="0.5 0.5 0.5"
           ambient="0.2 0.2 0.2"
           directional="true"
           castshadow="true"/>

        <!-- Target marker -->
        <!-- <site name="target" pos="0 0 0.25" size="0.03" rgba="0 1 0 0.5" type="sphere"/> -->

        <!-- ===== Quadrotor Base ===== -->
        <body name="base" pos="0 0 0.25">
            <joint name="free_joint" type="free"/>
            <inertial pos="0 0 0" mass="1.5" diaginertia="0.008 0.008 0.015"/>

            <!-- Main body -->
            <geom name="base_body" type="box" size="0.1 0.1 0.03" rgba="0.2 0.2 0.8 1"
                  contype="1" conaffinity="1" mass="0"/>

            <!-- X configuration arms (visual, no mass) -->
            <geom type="capsule" fromto="0 0 0 0.15 0.15 0" size="0.01" class="visual"/>
            <geom type="capsule" fromto="0 0 0 -0.15 0.15 0" size="0.01" class="visual"/>
            <geom type="capsule" fromto="0 0 0 -0.15 -0.15 0" size="0.01" class="visual"/>
            <geom type="capsule" fromto="0 0 0 0.15 -0.15 0" size="0.01" class="visual"/>

            <!-- Propellers (visual) -->
            <geom type="cylinder" pos="0.15 0.15 0" size="0.05 0.005" rgba="0.1 0.1 0.1 0.7" class="visual"/>
            <geom type="cylinder" pos="-0.15 0.15 0" size="0.05 0.005" rgba="0.1 0.1 0.1 0.7" class="visual"/>
            <geom type="cylinder" pos="-0.15 -0.15 0" size="0.05 0.005" rgba="0.1 0.1 0.1 0.7" class="visual"/>
            <geom type="cylinder" pos="0.15 -0.15 0" size="0.05 0.005" rgba="0.1 0.1 0.1 0.7" class="visual"/>

            <!-- Landing legs (visual, no mass) -->
            <geom type="capsule" fromto="0.08 0.08 -0.03 0.08 0.08 -0.20" size="0.008" rgba="0.3 0.3 0.3 1" class="visual"/>
            <geom type="capsule" fromto="-0.08 0.08 -0.03 -0.08 0.08 -0.20" size="0.008" rgba="0.3 0.3 0.3 1" class="visual"/>
            <geom type="capsule" fromto="-0.08 -0.08 -0.03 -0.08 -0.08 -0.20" size="0.008" rgba="0.3 0.3 0.3 1" class="visual"/>
            <geom type="capsule" fromto="0.08 -0.08 -0.03 0.08 -0.08 -0.20" size="0.008" rgba="0.3 0.3 0.3 1" class="visual"/>
            <!-- Landing feet (contact with ground) -->
            <geom type="sphere" pos="0.08 0.08 -0.20" size="0.012" rgba="0.3 0.3 0.3 1" mass="0"/>
            <geom type="sphere" pos="-0.08 0.08 -0.20" size="0.012" rgba="0.3 0.3 0.3 1" mass="0"/>
            <geom type="sphere" pos="-0.08 -0.08 -0.20" size="0.012" rgba="0.3 0.3 0.3 1" mass="0"/>
            <geom type="sphere" pos="0.08 -0.08 -0.20" size="0.012" rgba="0.3 0.3 0.3 1" mass="0"/>

            <!-- Platform site for force application -->
            <site name="platform_site" pos="0 0 0" size="0.01"/>

            <!-- ===== Robot Arm ===== -->
            <body name="link1" pos="0 0 -0.05">
                <joint name="joint1" type="hinge" axis="0 1 0" damping="0.02"/>
                <inertial pos="0 0 -0.06" mass="0.15" diaginertia="0.0002 0.0002 0.00005"/>

                <!-- Vertical link going down -->
                <geom name="link1_geom" type="capsule" fromto="0 0 0 0 0 -0.12"
                      size="0.015" rgba="0.8 0.2 0.2 1" mass="0"/>

                <body name="link2" pos="0 0 -0.12">
                    <joint name="joint2" type="hinge" axis="0 1 0" damping="0.02"/>
                    <inertial pos="0.08 0 0" mass="0.12" diaginertia="0.00015 0.00015 0.00003"/>

                    <!-- Horizontal link (90 deg bend) -->
                    <geom name="link2_geom" type="capsule" fromto="0 0 0 0.16 0 0"
                          size="0.012" rgba="0.2 0.8 0.2 1" mass="0"/>

                    <!-- ===== Gripper ===== -->
                    <body name="ee" pos="0.16 0 0">
                        <inertial pos="0 0 0" mass="0.05"
                                  diaginertia="0.00005 0.00008 0.00008"/>

                        <!-- Palm -->
                        <geom name="palm_geom" type="box" size="0.02 0.032 0.015"
                              rgba="0.25 0.25 0.25 1"
                              friction="1.0 0.05 0.005"/>

                        <!-- Left finger: slides along y-axis, range 0=open → -0.024=closed -->
                        <body name="finger_left" pos="0.02 0.026 0">
                            <joint name="gripper_left_joint" type="slide" axis="0 1 0"
                                   range="-0.024 0" damping="2.0"/>
                            <inertial pos="0.028 0 0" mass="0.025"
                                      diaginertia="0.000010 0.000015 0.000015"/>
                            <geom name="finger_left_geom" type="capsule"
                                  fromto="0 0 0 0.058 0 0" size="0.008"
                                  rgba="0.75 0.38 0.1 1"
                                  friction="1.8 0.12 0.01"
                                  condim="4" solimp="0.9 0.95 0.001" solref="0.02 1"/>
                        </body>

                        <!-- Right finger: slides along y-axis, range 0=open → +0.024=closed -->
                        <body name="finger_right" pos="0.02 -0.026 0">
                            <joint name="gripper_right_joint" type="slide" axis="0 1 0"
                                   range="0 0.024" damping="2.0"/>
                            <inertial pos="0.028 0 0" mass="0.025"
                                      diaginertia="0.000010 0.000015 0.000015"/>
                            <geom name="finger_right_geom" type="capsule"
                                  fromto="0 0 0 0.058 0 0" size="0.008"
                                  rgba="0.75 0.38 0.1 1"
                                  friction="1.8 0.12 0.01"
                                  condim="4" solimp="0.9 0.95 0.001" solref="0.02 1"/>
                        </body>

                        <!-- Site between fingertips -->
                        <!-- <site name="end_effector" pos="0.078 0 0" size="0.008"
                              rgba="1 0 0 0.8" type="sphere"/> -->
                    </body>
                </body>
            </body>

        </body>

    </worldbody>

    <!-- Actuators: joint motors; platform force/torque via xfrc_applied -->
    <!-- Gripper convention (prismatic): gripper_left ctrl < 0 = close; gripper_right ctrl > 0 = close -->
    <actuator>
        <motor name="joint1_torque"  joint="joint1"              gear="1" ctrllimited="true" ctrlrange="-5 5"/>
        <motor name="joint2_torque"  joint="joint2"              gear="1" ctrllimited="true" ctrlrange="-5 5"/>
        <motor name="gripper_left"   joint="gripper_left_joint"  gear="1" ctrllimited="true" ctrlrange="-10 1"/>
        <motor name="gripper_right"  joint="gripper_right_joint" gear="1" ctrllimited="true" ctrlrange="-1 10"/>
    </actuator>

</mujoco>